Workbook

Sheet About
A1: How to Use this Document: | B1: Details | C1: Additional Notes
A2: Installed Sensors | B2: This tab includes a comprehesive list of all the sensors, address where they are located, name and contact info for the person of contact, whether or not it needs maintenance done, whether or not there is a hotspot installed, and maintenance notes.
A3: Sensor Tracking | B3: This tab has a list of all the sensors that we own and what their status is. They are either Green: Deployed, Blue: Not deployed, ready for deployment, Orange: Not collocated, Red: Not functioning, and Purple: Missing. A bunch of the details about the sensors, including their ID number, in included on each of the lines.
A4: Hotspot Tracking | B4: This tab has a list of the hotspots that are occasionally needed for sensor deployment. If a hot spot is deployed, the associated sensor it is being used with is recorded
A5: Weekly Sensor Checks | B5: This tab is where the weekly sensor checks are documented. The instruction document on how to do sensor checks is included in the Air Quality Neighborhood sensoring Project Google Drive in the Field Maintenance folder. If they appear to be functioning, input a green yes, if not a red no, and if it's hard to tell, put down as a yellow maybe.
A6: Potential Opportunities | B6: This tab is slightly out of date in that some of these locations and contacts already have a sensor installed at that location, but other contacts are potential opportunities to reach back out to who had said at one point that they would be interested in hosting a sensor at their home or business. Use this tab if you are in need of more sensor locations and want to use the list of people who are already interested.
A7: Target Zip Codes | B7: This tab lists the zip codes that we are targeting through this project, the number of potential opportunities in each zip code, and the number of sensors located at each one (althrough this may also be a little out of date).
A8: Deployment Log | B8: This tab is intended to be a list of information about sensor deployments (i.e., which sensor was deployed to which location between which dates) which is formatted to be easily readible by machine for integration into automated data analysis.
A9: Site Descriptions | B9: This tab is intended to provide categorical data on the sensor site specifically or the direct area around them to allow for more critical analysis of the direct surroundings that could influence the measures at the site. | C9: • all measurements are in feet • land use type is a generalization of MORPC's land use data (govt is mostly libraries) • the housing density is a very approximate estimation of the density based on MORPC's land use and using a 500-foot buffer for the area around each location (if ANY residential was found within 500 feet, I used the parcel density from our land use model for these numbers)
A10: Collocation | B10: This tab included a lot of data about the sensors that have been collocated.

Sheet Community Displays
A1: Organization | B1: Primary Contact Name | C1: Email | D1: Phone | E1: Number of visual displays | F1: Link to file containing list and location information | G1: Secondary Contact information (Separated with commas) | H1: Additional Comments

Sheet Cell References
D3: Sensor Tracking | E3: Hot Spot Tracking | F3: Weekly Sensor Checks
C4: Green | D4: Deployed | E4: Deployed | F4: Good
C5: Blue | D5: Not Deployed,Ready for Deployment | E5: Not deployed | F5: Maybe
C6: Orange | D6: Not Collocated | E6: Not functioning | F6: Bad
C7: Red | D7: Not Functioning | F7: Not Deployed
C8: Purple | D8: Missing | F8: Removed

Sheet PurpleAir Sensor Tracking
A1: Sensor ID | B1: Type | C1: Sensor MAC ID | D1: Status | E1: Location | F1: Start Date of Deployment | G1: Needs Maintenance *** = take action %%% = contact Purple Air | H1: Notes | I1: Hotspot Needed? | J1: Hotspot Serial # | K1: Mobile hotspot password
A2: MORPC_001 | B2: PA-II-SD Air Quality Sensor | C2: 80:7D:3A:2B:DA:A0 | D2: Not Collocated | E2: not deployed | F2: 43943 | G2: Undetermined status - needs tested | O2: Status key:
A3: MORPC_002 | B3: PA-II-SD Air Quality Sensor | C3: 80:7D:3A:2B:5F:25 | D3: Missing | E3: not deployed | F3: 43978 | H3: Not found during equipment check 1/18/24 | O3: Not Deployed,Ready for Deployment
A4: MORPC_003 | B4: PA-II-SD Air Quality Sensor | C4: 80:7d:3a:2b:bb:25 | D4: Needs Maintenance | E4: Installed at Franklin Park Conservatory (stopped working and was replaced with MORPC_24) | F4: 43945 | G4: Won't power up | H4: Mauro was able to get sensor to power up; needs to be tested for data collection 1/18/2024 | O4: Not Functioning
A5: MORPC_004 | B5: PA-II-SD Air Quality Sensor | C5: 80:7d:3a:2b:bb:28 | D5: Missing | E5: Broad and High | F5: 43927 | H5: Went missing during protests | O5: Missing
A6: MORPC_005 | B6: PA-II-SD Air Quality Sensor | C6: 80:7d:3a:2b:81:63 | D6: Not Collocated | E6: not deployed | F6: 43921 | G6: Undertermined status - needs tested | O6: Not Collocated
A7: MORPC_006 | B7: PA-II-SD Air Quality Sensor | C7: 80:7D:3A:2B:81:5F | D7: Deployed | E7: Installed at 441 Nashoba Avenue | F7: 44464 | O7: Deployed
A8: MORPC_007 | B8: PA-II-SD Air Quality Sensor | C8: 80:7D:3A:2B:61:7A | D8: Deployed | E8: Installed at Shepard Branch Library | F8: 5/31/22 ; online as of 8/11/22 | O8: Needs Maintenance
A9: MORPC_008 | B9: PA-II-SD Air Quality Sensor | C9: 84:F3:EB:6F:79:E7 | D9: Needs Maintenance | E9: not deployed | G9: "Power socket slid back" needs tested | H9: Mauro was able to reset the power socket placement; needs to be tested for data collection 1/18/2024
A10: MORPC_009 | B10: PA-II-SD Air Quality Sensor | C10: 80:7D:3A:2B:D8:28 | D10: Not Functioning | E10: not deployed | G10: *** No SD card detected
A11: MORPC_010 | B11: PA-II-SD Air Quality Sensor | C11: 84:F3:EB:7B:C8:F6 | D11: Not Functioning | E11: not deployed - taken out of rotation for maintenance | F11: 44420 | G11: %%% Only one sensor is working | H11: Removed from installation and retired
A12: MORPC_011 | B12: PA-II-SD Air Quality Sensor | C12: 84:F3:EB:7B:C9:E2 | D12: Needs Maintenance | E12: not deployed | G12: "SD card lost inside" see note on sensor | H12: Mauro was able to retrieve the SD card and confirmed power-up of sensor. Needs to be tested. 1/18/2024
A13: MORPC_012 | B13: PA-II-SD Air Quality Sensor | C13: 80:7D:3A:2B:61:7F | D13: Deployed | E13: Installed at 1221 Chesapeake
A14: MORPC_013 | B14: PA-II-SD Air Quality Sensor | C14: 80:7D:3A:2B:DC:FE | D14: Not Functioning | E14: not deployed | G14: %%% Wifi signal from monitor not showing up | H14: Get data from SD card?
A15: MORPC_014 | B15: PA-II-SD Air Quality Sensor | C15: 80:7D:3A:2B:DA:86 | D15: Deployed | E15: Installed at 2768 Audubon Road, Linden
A16: MORPC_015 | B16: PA-II-SD Air Quality Sensor | C16: 80:7D:3A:2C:11:9C | D16: Not Functioning | E16: not deployed | G16: %%% Temp and humidity data missing
A17: MORPC_016 | B17: PA-II-SD Air Quality Sensor | C17: 80:7D:3A:2B:DC:34 | D17: Missing | E17: Installed at 1220 Striebel Road, Now not deployed | H17: Not found in equipment closet on 1/18/24
A18: MORPC_017 | B18: PA-II-SD Air Quality Sensor | C18: 80:7D:3A:2B:DA:FA | D18: Deployed | E18: Installed at 1575 Studer Ave | F18: 44754
A19: MORPC_018 | B19: PA-II-SD Air Quality Sensor | C19: 80:7D:3A:2B:DA:84 | D19: Needs Maintenance | E19: not deployed | G19: *** Won't power up? | H19: MDH shows powering up on 1/18/24
A20: MORPC_019 | B20: PA-II-SD Air Quality Sensor | C20: 80:7D:3A:2B:5F:37 | D20: Not Functioning | E20: not deployed | G20: Won't power up | H20: Mauro inspected during equipment check 1/18/24. The power input area that connects to the main green chip is not soldered on so the sensor won't power up.
A21: MORPC_020 | B21: PA-II-SD Air Quality Sensor | C21: 80:7D:3A:2B:5F:17 | D21: Not Functioning | E21: not deployed | G21: *** Channel B reading too low
A22: MORPC_021 | B22: PA-II-SD Air Quality Sensor | C22: 10:52:1C:44:DB:FA | D22: Not Functioning | E22: Not deployed
A23: MORPC_022 | B23: PA-II-SD Air Quality Sensor | C23: 10:52:1C:42:18:49 | D23: Not Functioning | E23: Removed from 1575 Studer Ave and replaced w/ MORPC_17 on 7/12/22. 9/28/22 Monitor re-deployed at Whitehall library. Found in equipment closet on 1/18/2024. | F23: 44832 | H23: Check data and then ready to be sited. Found in equipment closet on 1/18/24
A24: MORPC_023 | B24: PA-II-SD Air Quality Sensor | C24: 10:52:1C:41:BA:50 | D24: Deployed | E24: installed with COTA at 5271 N High St | F24: 44509 | H24: Check data and then ready to be sited
A25: MORPC_024 | B25: PA-II-SD Air Quality Sensor | C25: A4:CF:12:FE:0:34 | D25: Not Functioning | E25: Installed at the Franklin Park Conservatory | G25: *** Poorly correlated with reference monitor during collocation | H25: Check data and then ready to be sited
A26: MORPC_025 | B26: PA-II-SD Air Quality Sensor | C26: FC:F5:C4:9E:44:D0 | D26: Deployed | E26: Installed at South High Library Branch | H26: Check data and then ready to be sited
A27: MORPC_026 | B27: PA-II-SD Air Quality Sensor | C27: FC:F5:C4:9E:74:4C | D27: Deployed | E27: installed with COTA at 1390 Cleveland Ave | F27: 44509 | H27: Check data and then ready to be sited
A28: MORPC_027 | B28: PA-II-SD Air Quality Sensor | C28: 10:52:1C:41:43:FC | D28: Deployed | E28: Installed at Bexley City Hall, 2242 E Main St | F28: 44692
A29: MORPC_028 | B29: PA-II-SD Air Quality Sensor | C29: 10:52:1C:41:68:25 | D29: Deployed | E29: installed with COTA at 1125 E main st. | F29: 44509
A30: MORPC_029 | B30: PA-II-SD Air Quality Sensor | C30: 10:52:1C:42:21:3B | D30: Not Functioning | E30: Removed from Indianola Informal on 1/10/22 | G30: Removed from Indianola Informal on 1/10/22 - no longer turning on
A31: MORPC_030 | B31: PA-II-SD Air Quality Sensor | C31: 10:52:1C:41:35:C1 | D31: Deployed | E31: Installed at COSI - 333 W Broad St | F31: 44673
A32: MORPC_031 | B32: PA-II-SD Air Quality Sensor | C32: 10:52:1C:4D:A8:92 | D32: Not Functioning | E32: Installed at 1295 Glenn Ave, Grandview | G32: Removed 8/19/2024; | H32: Replaced withMORPC_061 since it was malfunctioning
A33: MORPC_032 | B33: PA-II-SD Air Quality Sensor | C33: A4:CF:12:FE:0:3C | D33: Deployed | E33: 2527 Nassau Dr., Blacklick (removed 2/17/23 from Nassau Dr and placed at Indianola Informal 4/4/23)
A34: MORPC_033 | B34: PA-II-SD Air Quality Sensor | C34: 10:52:1C:41:FF:70 | D34: Deployed | E34: Installed at 897 W Broad St, Columbus
A35: MORPC_034 | B35: PA-II-SD Air Quality Sensor | C35: 10:52:1C:41:BD:24 | D35: Not Functioning | E35: installed at Whitehall branch library- 9/28/22 | G35: monitor replaced becase it was not functioning
A36: MORPC_035 | B36: PA-II-SD Air Quality Sensor | C36: 10:52:1C:41:B1:4 | D36: Deployed | E36: Installed at 164 Hayden Ave, Columbus
A37: MORPC_036 | B37: PA-II-SD Air Quality Sensor | C37: 10:52:1C:44:E9:1C | D37: Deployed | E37: 2650 London Groveport Rd, Grove City | F37: 44580
A38: MORPC_037 | B38: PA-II-SD Air Quality Sensor | C38: 10:52:1C:41:CD:F1 | D38: Deployed | E38: Installed at Blendon Senior Center | F38: 44544
A39: MORPC_038 | B39: PA-II-SD Air Quality Sensor | C39: 10:52:1C:41:77:E | D39: Not Deployed,Ready for Deployment | E39: Installed at Hilltop YMCA - Removed 8/25/2025 | F39: 44700 | H39: Removed from Hilltop YMCA roof on 8/25/2025. Sensor wasn't consistenly staying online. Sensor still functions and channels are agreeing at 100%. Data has been archived and sensor is ready for re-deployment.
A40: MORPC_039 | B40: PA-II-SD Air Quality Sensor | C40: 10:52:1C:41:62:F5 | D40: Deployed | E40: Installed at Kingston Center in Grove City | F40: 44531
...

Sheet Installed Sensors
A1: Sensor ID | B1: Neighborhood | C1: Address | D1: Location Type | E1: ZIP Code | F1: Contact Name | G1: Contact Email | H1: Phone Number | I1: Hotspot installed? (5 total) | J1: Notes
A2: MORPC_003 | B2: Old Town East | C2: 1777 E Broad St | D2: Franklin Park Conservatory | E2: 43203 | F2: Garry Clarke | G2: gclarke@fpconservatory.org | H2: 614-715-8074 | J2: , Columbus- Dot on the map is 2 blocks south 2/24/22, reset sensor and learned after resetting that the B channel on the sensor is broken. Will need to replace sensor. 3/3/22, replaced sensor to a new sensor, MORPC_24.
A3: MORPC_006 | B3: Hilltop | C3: 441 Nashoba Ave, Hilltop | D3: Private Residence | E3: 43223 | F3: Megan Fiscus | G3: megantheresefiscus@gmail.com | I3: Yes | J3: 1/7/22, installed wifi hotspot.
A4: MORPC_007 | B4: Shepard | C4: 850 N Nelson Rd, Columbus | D4: Library | E4: 43219 | F4: Andrew Kistler | G4: akistler@columbuslibrary.org | H4: 614-849-1074 | J4: 5/31/22, sensor installed but could not be connected to wifi. Waiting on library IT staff to create a separate wifi network for the sensor to connect to. Once IT has that created, will go back out to get sensor online. 6/16/22, went out to connect sensor to wifi and sensor would not broadcast its wifi unplugged it for the weekend and will come back to try again. 6/23/22, went out to connect sensor and the new wifi network was not discoverable to the purpleair as a network it could connect to. Reached out to their IT and they are making adjustments to the network. 7/26/22, After hearing back from IT about network adjustments, went back out to connect the sensor and after putting the wifi password in, I keep getting an error message saying "wifi disconnected" reaching back out to IT. 8/10/22, went back out after IT said the building was blocking the wifi signal. Decided that we would try to relocate the sensor to a light pole in the parking lot that was further away from the building. Upon trying to connect the sensor to wifi, I kep getting a "wifi disconnected" message. Noticed the wifi signal was very poor - thinking that is why the sensor would not connect. Reached back out to IT and they are going to come out with me next time to help troubleshoot the wifi network. 8/11/22, met CML IT staff on site. They said the signal was not turned up enough, it was adjusted and the sensor was successfully connected and is now transmitting data online!!!
A5: MORPC_012 | B5: Grandview Heights | C5: 1221 Chesapeake Ave | D5: Local Business (Steven's Catering) | E5: 43212 | F5: Kristian Sims | G5: kristiansims42@gmail.com | J5: 11/23/22, reset the sensor bc the channels were not tracking well.
A6: MORPC_014 | B6: Linden | C6: 2768 Audubon Road | D6: Private Residence | E6: 43211 | F6: Benjamin Keith | G6: benlkeith@gmail.com
A7: MORPC_016 | B7: Whitehall | C7: 1220 Striebel Rd | E7: 43227 | F7: Carol Stitzlein | G7: bflycook@aol.com | H7: 614-236-4915
A8: MORPC_017 | B8: Far South | C8: 1575 Studer Ave | D8: Private Residence | E8: 43207 | F8: Katharine Harding | G8: katharine6547@gmail.com | I8: Yes | J8: 7/12/22, MORPC_17 was installed in place of MORPC_22. MORPC_22 was still transmitting it's hotspot and showing up on my list of wifi connections, but the sensor would not connect to wifi, so I decided to switch it out and will troubleshoot with MORPC_22 to see if I can get it up and running again for another site.
A9: MORPC_022 | B9: Whitehall | C9: 4445 E Broad St | D9: Library | E9: 43213 | F9: Andrew Kistler | G9: akistler@columbuslibrary.org | J9: 9/28/22, MORPC_34 was replaced with MORPC_22. 1/26/23, sensor was reset because it was offline. 2/9/23, sensor was removed because there was no channel agreement. Prince took to MORPC to test it out to see if it still works
A10: MORPC_022 | B10: Far South | C10: 1575 Studer Ave | D10: Private Residence | E10: 43207 | F10: Katharine Harding | G10: katharine6547@gmail.com | J10: 6/6/22, noticing that the sensor drops off and jumps back onto the map multiple times a day. Going to see if a hotspot can be installed for a stronger WiFi connection. Site host said they have been having trouble with their internet service. 6/16/22, went out to install a hotspot because sensor kept dropping off the map. Called purpleair to have the sensor reset, but sensor would not disconnect from the resident's wifi connection. Left sensor unplugged in hopes that would help it disconnect. 6/23/22, plugged sensor back in when I got there and it immedistaly connected back to host's wifi connection. removed sensor from the property and sat in a nearby parking lot for 30 mins in hopes the sensor would disconnect since it was out of range from the network. took sensor back and it still connected to hosts wifi. took sensor home with me in hopes that it would help disconnect from the wifi. 7/12/22, Took sensor back to site host's property to see if I could successfully connect it to the hotspot. Sensor was still immediately connecting back to the host's home WiFi. I brought a second sensor if this was the case and decided to install MORPC_17 in place of MORPC_22.
A11: MORPC_023 | B11: Clintonville | C11: 5271 N High St | D11: COTA Transfer Station | E11: 43214 | F11: Russell Joehlin | G11: rjoehlin@alterrare.com | I11: No | J11: 2/28/22, reset sensor bc temperature/humidity measurements had been stuck at the same readings for a while. 12/19/22, noticed that all 3 COTA sensors went offline on the same day and were no longer transmitting data to the map. Reached out to site host who said that the WiFi to all COTA sites is down for reasons out of their control. He said he will reach out to me when the WiFi is back up and running. 1/4/23, reached back out to site host to get an update on the WiFi situation. Host said there is no change and that WiFi for all COTA sites is still offline and that he will reach out when WiFi is back on. 3/27/23, reached back out to site host for an update and was told the WiFi is still out. 5/17/23, reached back out to site host for am update on WiFi. Have not received a reply back yet. 11/7/23, reached out to site host for a WiFi update..have not received a reply yet.
A12: MORPC_024 | B12: Old Town East | C12: 1777 E Broad St, Columbus- Dot on the map is 2 blocks south | D12: Franklin Park Conservatory | E12: 43203 | F12: Garry Clarke | G12: gclarke@fpconservatory.org | H12: 614-715-8074 | J12: 3/3/22, sensor deployed. 5/24/22, visited FPC because sensor had been offline for several weeks. Ground fault for the light pole was tripped so the sensor was not receiving power and the wifi booster in the nearby conference room was unplugged. We also did a site assessment and identified the support greenhouse as a second site if the light pole location continues to fail. 6/15/22, moved sensor from light pole to greenhouse nearby. 3/27/23, Reached out to site host because sensor had been offline for 5 days. Host reset sensor and it did not turn back on. Host said he thinks sensor was damaged from a storm that happened last week.
A13: MORPC_025 | B13: Far South | C13: 3540 S High St, Columbus | D13: Library | E13: 43207 | F13: Andrew Kistler | G13: akistler@columbuslibrary.org | H13: 614-849-1074 | I13: Yes | J13: 2/24/22, installed wifi hotspot.
A14: MORPC_026 | B14: Linden | C14: 1390 Cleveland Ave | D14: COTA Transfer Station | E14: 43211 | F14: Russell Joehlin | G14: rjoehlin@alterrare.com | I14: No | J14: 9/8/22, sensor was reset because it had been falling off the real-time map. Russell said he will look into having a wifi access point placed near the sensor to help strengthen the wifi signal. 12/19/22, noticed that all 3 COTA sensors went offline on the same day and were no longer transmitting data to the map. Reached out to site host who said that the WiFi to all COTA sites is down for reasons out of their control. He said he will reach out to me when the WiFi is back up and running. 1/4/23, reached back out to site host to get an update on the WiFi situation. Host said there is no change and that WiFi for all COTA sites is still offline and that he will reach out when WiFi is back on. 3/27/23, reached back out to site host for an update and was told the WiFi is still out. 5/17/23, reached back out to site host for am update on WiFi. Have not received a reply back yet. 11/7/23, reached out to site host for a WiFi update..have not received a reply yet.
A15: MORPC_027 | B15: Bexley | C15: 2242 E Main St, Bexley | D15: City Hall Building | E15: 43209 | F15: Elizabeth Ellman | G15: eellman@bexley.org | H15: 614-559-4250 | I15: No | J15: 5/11/22, sensor installed at City Hall
A16: MORPC_028 | B16: Old Town East | C16: 1125 East Main St, Columbus | D16: COTA Transfer Station | E16: 43205 | F16: Russell Joehlin | G16: rjoehlin@alterrare.com | I16: No | J16: 3/8/22, data seems to stop collecting multiple times in a day. went out to the site and power cord was not plugged in/there was not enough slack last time, jennie said a second zip tie. 4/13/22, reached out to site host because sensor was offline after performing weekly network check. Site host reset the sensor for us and sensor is back online. 5/31/22, went out to troubleshoot sensor. noticed sensor was offline after weekly netowrk check. unplugged sensor to reset and sensor popped back up on the map. 8/9/22, went out because sensor was offline. Reset the sensor and it still did not pop up on the map wifi signal is very weak. Going to reach out to our contact and see what wifi network it is connected to and try to figure out if we need a hotspot or if we can connect to another network in the building with a stronger signal.12/19/22, noticed that all 3 COTA sensors went offline on the same day and were no longer transmitting data to the map. Reached out to site host who said that the WiFi to all COTA sites is down for reasons out of their control. He said he will reach out to me when the WiFi is back up and running. 1/4/23, reached back out to site host to get an update on the WiFi situation. Host said there is no change and that WiFi for all COTA sites is still offline and that he will reach out when WiFi is back on. 3/27/23, reached back out to site host for an update and was told the WiFi is still out. 5/17/23, reached back out to site host for am update on WiFi. Have not received a reply back yet. 11/7/23, reached out to site host for a WiFi update..have not received a reply yet.
A17: MORPC_029 | B17: Clintonville | C17: 251 E Weber Rd | E17: 43202 | F17: Jared Laughbaum | G17: jlaughbaum7833@columbus.k12.oh.us | J17: 9/19/22, went out because sensor has been offline since the beginning of summer. Had to wait until school started back up (for the building to open) before I could get to the sensor to troubleshoot. Checked the power to the outlet which worked, but sensor would not show up on the map after being reset. Layla is going to have it reset by purpleair tech and then will schedule another maintenance meeting. 1/10/22, went back out and identified that MORPC_29 is no longer working. sensor has been taken down and we will be replacing with MORPC_21.
A18: MORPC_030 | B18: COSI | C18: 333 W Broad S, Columbus | D18: COSI - Big Science Park | E18: 43215 | F18: Andy Achiele | G18: aaichele@cosi.org | H18: 614-629-3110 | I18: No
A19: MORPC_031 | B19: Grandview Heights | C19: 1295 Glenn Ave | D19: Private Residence | E19: 43212 | F19: Andy Leber | G19: aleber@gmail.com | I19: No | J19: REMOVED 8/19/2024
A20: MORPC_032 | B20: Clintonville | C20: 251 E Weber Rd, Clintonville | D20: Indianola Informal K-8 School | E20: 43202 | F20: Jared Laughbaum | G20: jlaughbaum7833@columbus.k12.oh.us | I20: Yes | J20: 4/4/2023, MORPC_32 installed
A21: MORPC_032 | B21: Eastland | C21: 2527 Nassau Drive | D21: Private Residence | E21: 43232 | F21: Jessica Brewer | G21: jessica.brewer02@gmail.com | J21: 11/11/22, Host reached out to ask when the sensor will be removed becase they will be moving. Given updates provided by team member (Brandi), host agreed to host the sensor till April, 2023. 2/17/23, sensor removed from site because host was moving to a new location.
A22: MORPC_033 | B22: Franklinton | C22: 897 W Broad St, Columbus | D22: Local Business (Franklinton Cycle Works) | E22: 43222 | F22: Jonathan Youngman | G22: info@franklintoncycleworks.org | H22: 614-407-5161 | J22: 3/24/22, data seems to stop. 4/7/2022, went out and found that the sensor accidentally got unplugged. Removed on 3/7/2024.
A23: MORPC_034 | B23: Whitehall | C23: 4445 E Broad St (Library) | E23: 43213 | F23: Andrew Kistler | G23: akistler@columbuslibrary.org | J23: 9/20/22, Jennie went out and reset the sensor because it was stuck at very high values for about a week. She found a spider web in the sensor. 9/26/22, Jennie went back out to reset the sensor because Channel A data was missing. The reset did not work, so the plan is to replace the sensor.
A24: MORPC_035 | B24: Franklinton 1 | C24: 164 Hayden Ave, Columbus | D24: Private Residence | E24: 43222 | F24: Jason Boylan | G24: boylanjasonc@gmail.com | H24: 614-406-4371 | I24: Yes
A25: MORPC_036 | B25: Grove City | C25: 2650 London Groveport Rd | D25: Jackson Twshp Fire Department | E25: 43123 | F25: Todd Hurley | G25: thurley@grovecityohio.gov | I25: No | J25: Removed on 3/11/2024.
A26: MORPC_037 | B26: Blendon | C26: 6330 S Hempstead Rd, Westerville | D26: Senior Center | E26: 43081 | F26: John Giamarco | G26: jgiamarco@blendontwp.org | I26: No
A27: MORPC_038 | B27: Hilltop | C27: 2879 Valleyview Drive | D27: Hilltop YMCA | E27: 43204 | F27: Theresa Whittington | G27: twhittington@ymcacolumbus.org | I27: No | J27: 5/19/22, sensor was moved from Hilltop Library and installed at Hilltop YMCA. 1/9/22, sensor was moved to a different location on the roof of the YMCA and the sensor's cord was replaced because it was cut by someone and no longer worked. 8/25/2025, MORPC_038 was removed as it had been offline since 10/7/2024.
A28: MORPC_038 | B28: Hilltop | C28: 511 S Hague Ave | D28: Library | E28: 43204 | F28: Andrew Kistler | G28: akistler@columbuslibrary.org | I28: No | J28: 4/13/22, After weekly air quality network check, the sensor was offline. Reached out to site host to see if the sensor was unplugged or if the WiFi was out. Site host said the sensor was unplugged and plugged it back in. Sensor is back online and transmitting data again. 4/26/22, Sensor was unplugged again, so Anna & Layla went out to take a look at the site and discuss moving the sensor to a better location. After talking with the maintenance manager, we were told that the outlet is often used to charge phones and this is most likely why the sensor kept being unplugged. We came to the decision that the best way to move forward would to be to relocate the sensor to another location in Hilltop, possibly the YMCA. 5/16/22, sensor was removed from library in preparation to be placed at Hilltop YMCA
A29: MORPC_039 | B29: Grove City | C29: 3226 Kingston Ave, Grove City | D29: City Building (Parks & Rec) | E29: 43123 | F29: Todd Hurley | G29: thurley@grovecityohio.gov | H29: 614-277-1725 | J29: 8/9/22, sensor had been down for a month. Was working virtually with Grove City IT who tried resetting it a few times without luck of getting it back online. After asking purple air to archive the data and reset the sensor, it was still not broadcasting its network. We turned off the wifi network it was connected to, unplugged the sensor, re-plugged it in and waited about 10 mins before it started broadcasting its networks again. We connected it to my hotspot so it wouldn't automatically connect back to the previous wifi, turned the old wifi network back on and successfully connected it back to the wifi network it was connected to before. We also learned that where the sensor was mounted on the building, the wifi was blocked. We moved the sensor 5 feet to the left and everything worked perfectly.
A30: MORPC_040 | B30: Smoky Row/OH EPA sensoring site | C30: 7560 Smoky Row Rd, Columbus | D30: EPA Regulatory Monitoring Site | E30: 43235 | F30: Austin Deschene | G30: austin.deschene@epa.ohio.gov | H30: 614-644-3617 | I30: No
A31: MORPC_050 | B31: Franklinton 2 | C31: 897 W Broad St, Columbus | D31: Franklinton Cycle Works | E31: 43222 | F31: Jonathan Youngman | G31: info@franklintoncycleworks.org | H31: 614-407-5161 | I31: No | J31: Sensor is located on back of building above the awning out to the back door. It is screwed into the side of the cement block. A ladder is needed to access the sensor.
A32: MORPC_051 | B32: Franklinton 4 | C32: 133 S Cypress Ave, Columbus | D32: Private Residence | E32: 43222 | F32: Fawn Staten | G32: fdstaten@yahoo.com | H32: 614-774-3980 | I32: No | J32: Installed on 2/24/2025
A33: MORPC_052 | B33: Old Town East | C33: 1777 E Broad St, Columbus | D33: Franklin Park Conservatory | E33: 43203 | F33: Chris McDonald | G33: cmcdonald@fpconservatory.org | H33: 614-715-8141 | I33: No | J33: Sensor is located at the greenhouses next to the Wells Barn. The greenhouse is accessed by a locked gate. You will need a ladder to access the sensor. 7/8/25 - Ethan Hug connected us to new point of contact, Jim Butch, so we can access the sensor moving forward. New POC will be Chris McDonald and contact info updated
A34: MORPC_053 | B34: Far South | C34: 711 Southwood Ave, Columbus | D34: IMPACT Community Action | E34: 43207 | F34: Katie Devlin & Josh Kessler | G34: kdevlin@impactca.org & jkessler@impactca.org | H34: 614-371-1245 | I34: Yes | J34: Sensor is located on the roof of IMPACT attached to an onld antenna. Hotspot and power cord are fed through a small building that houses electrical/AC units.
A35: MORPC_054 | B35: Driving Park | C35: 1833 Kent Street, Columbus | D35: Private Residence | E35: 43205 | F35: Rene Coats | G35: renecoats@aol.com | H35: 614-270-9499 | I35: No | J35: Attached to Mr. John Coats' HAM radio tower facing Rhoads Avenue. Has a weak signal but is broadcasting.
A36: MORPC_055 | B36: Scioto Grove | C36: 5723 Paul Talbott Circle | D36: Private Residence | E36: 43123 | F36: Judith Bartley | G36: bartleju@gmail.com | H36: 859-652-4440 | I36: No | J36: Attached to the rear of the home on a gutter downspout, facing a very forested area of Scioto Grove Metro Park.
A37: MORPC_060 | B37: Hilliard | C37: 3515 Leap Road | D37: Private Residence | E37: 43026 | F37: Kyle Benzle | G37: kbe@gmx.us | H37: 614-505-9532 | I37: No | J37: Located on a small pole that houses a reciever for an automatic electric lawn mower. Faces Leap Road, which appeared to have a consistent flow of traffic.
A38: MORPC_061 | B38: Grandview Heights | C38: 1295 Glenn Ave | D38: Private Residence | E38: 43212 | F38: Andy Leber | G38: aleber@gmail.com | H38: 614-688-1372 | I38: No | J38: Installed on 8/19/2024, replacing 031 at this same location.
A39: MORPC_062 | B39: Grove City | C39: 2255 Home Road, Grove City | D39: Gantz Farmhouse Park | E39: 43123 | F39: Todd Hurley | G39: thurley@grovecityohio.gov | H39: 614-668-6812 | I39: No | J39: Installed on 8/22/2024
A40: MORPC_063 | B40: Knolls Thomas | C40: 3625 Pegg Avenue, Columbus | D40: Private Residence | E40: 43214 | F40: Dave Celebrezze | G40: david.celebrezze@westerville.org | H40: 614-668-1530 | I40: No | J40: Installed 9/12/2024. Removed 9/16/2025 - sensor stopped working.
...

Sheet Weekly Sensor Checks
A1: Sensor ID | B1: 44585 | C1: 44592 | D1: 44599 | E1: 44606 | F1: 44620 | G1: 44627 | H1: 44634 | I1: 44641 | J1: 44649 | K1: 44655 | L1: 44662 | M1: 44669 | N1: 44676 | O1: 44683 | P1: 44690 | Q1: 44704 | R1: 44712 | S1: 44718 | T1: 44725 | U1: 44732 | V1: 44750 | W1: 44753 | X1: 44767 | Y1: 44774 | Z1: 44781 | AA1: 44789 | AB1: 44795 | AC1: 44802 | AD1: 44810 | AE1: 44816 | AF1: 44823 | AG1: 44830 | AH1: 44837 | AI1: 44844 | AJ1: 44851 | AK1: 44858 | AL1: 44865 | AM1: 44872 | AN1: 44879 | AO1: 44886 | AP1: 44893 | AQ1: 44900 | AR1: 44908 | AS1: 44914 | AT1: 44921 | AU1: 44929 | AV1: 44935 | AW1: 44943 | AX1: 44949 | AY1: 44956 | AZ1: 44963 | BA1: 44970 | BB1: 44977 | BC1: 44984 | BD1: 44991 | BE1: 44998 | BF1: 45005 | BG1: 45012 | BH1: 45019 | BI1: 45026 | BJ1: 45033 | BK1: 45040 | BL1: 45047 | BM1: 45054 | BN1: 45061 | BO1: 45068 | BP1: 45076 | BQ1: 45082 | BR1: 45089 | BS1: 45096 | BT1: 45103 | BU1: 45110 | BV1: 45117 | BW1: 45124 | BX1: 45131 | BY1: 45138 | BZ1: 45145 | CA1: 45152 | CB1: 45159 | CC1: 45166 | CD1: 45173 | CE1: 45180 | CF1: 45187 | CG1: 45194 | CH1: 45201 | CI1: 45208 | CJ1: 45215 | CK1: 45222 | CL1: 45229 | CM1: 45236 | CN1: 45243 | CO1: 45250 | CP1: 45257 | CQ1: 45264 | CR1: 45271 | CS1: 45278 | CT1: 45285 | CU1: 45292 | CV1: 45299 | CW1: 45306 | CX1: 45313 | CY1: 45320 | CZ1: 45327 | DA1: 45334 | DB1: 45341 | DC1: 45348 | DD1: 45355 | DE1: 45362 | DF1: 45369 | DG1: 45376 | DH1: 45383 | DI1: 45390 | DJ1: 45397 | DK1: 45404 | DL1: 45411 | DM1: 45418 | DN1: 45425 | DO1: 45432 | DP1: 45439 | DQ1: 45446 | DR1: 45453 | DS1: 45460 | DT1: 45467 | DU1: 45474 | DV1: 45481 | DW1: 45488 | DX1: 45495 | DY1: 45502 | DZ1: 45509 | EA1: 45516 | EB1: 45523 | EC1: 45530 | ED1: 45537 | EE1: 45544 | EF1: 45551 | EG1: 45558 | EH1: 45565 | EI1: 45572 | EJ1: 45579 | EK1: 45586 | EL1: 45593 | EM1: 45600 | EN1: 45607 | EO1: 45614 | EP1: 45621 | EQ1: 45628 | ER1: 45635 | ES1: 45642 | ET1: 45649 | EU1: 45656 | EV1: 45663 | EW1: 45670 | EX1: 45677 | EY1: 45684 | EZ1: 45691 | FA1: 45698 | FB1: 45705 | FC1: 45712 | FD1: 45719 | FE1: 45726 | FF1: 45733 | FG1: 45740 | FH1: 45747 | FI1: 45754 | FJ1: 45761 | FK1: 45768 | FL1: 45775 | FM1: 45782 | FN1: 45789 | FO1: 45796 | FP1: 45803 | FQ1: 45810 | FR1: 45817 | FS1: 45824 | FT1: 45831 | FU1: 45838 | FV1: 45845 | FW1: 45852 | FX1: 45859 | FY1: 45866 | FZ1: 45873 | GA1: 45880 | GB1: 45887 | GC1: 45894 | GD1: 45901 | GE1: 45908 | GF1: 45915 | GG1: 45922 | GH1: 45929 | GI1: 45936 | GJ1: 45943 | GK1: 45950 | GL1: 45957 | GM1: 45964 | GN1: 45971 | GO1: 45978 | GP1: 45985 | GQ1: 45992 | GR1: 45999 | GS1: 46006 | GT1: 46013 | GU1: 46020 | GV1: 46027 | GW1: 46034 | GX1: 46041 | GY1: 46048 | GZ1: 46055 | HA1: 46062 | HB1: 46069 | HC1: 46076 | HD1: 46083 | HE1: 46090 | HF1: 46097 | HG1: 46104 | HH1: 46111 | HI1: 46118 | HJ1: 46125 | HK1: 46132 | HL1: 46139 | HM1: 46146 | HN1: 46153 | HO1: 46160 | HP1: 46167 | HQ1: 46174 | HR1: 46181 | HS1: 46188 | HT1: 46195 | HU1: 46202 | HV1: 46209 | HW1: 46216 | HX1: 46223 | HY1: 46230 | HZ1: 46237 | IA1: 46244 | IB1: 46251 | IC1: 46258
A2: MORPC_003 | B2: Bad | C2: Bad | D2: Good | E2: Bad | F2: Bad
A3: MORPC_006 | B3: Good | C3: Good | D3: Good | E3: Good | F3: Good | G3: Good | H3: Good | I3: Good | J3: Good | K3: Good | L3: Good | M3: Good | N3: Good | O3: Good | P3: Good | Q3: Good | R3: Good | S3: Good | T3: Maybe | U3: Good | V3: Good | W3: Good | X3: Good | Y3: Good | Z3: Good | AA3: Good | AB3: Good | AC3: Good | AD3: Good | AE3: Good | AF3: Good | AG3: Good | AH3: Good | AI3: Good | AJ3: Good | AK3: Good | AL3: Good | AM3: Good | AN3: Good | AO3: Good | AP3: Good | AQ3: Good | AR3: Maybe | AS3: Maybe | AT3: Maybe | AU3: Maybe | AV3: Good | AW3: Good | AX3: Good | AY3: Maybe | AZ3: Good | BA3: Good | BB3: Good | BC3: Good | BD3: Good | BE3: Good | BF3: Good | BG3: Good | BH3: Good | BI3: Good | BJ3: Good | BK3: Good | BL3: Good | BM3: Good | BN3: Good | BO3: Good | BP3: Good | BQ3: Good | BR3: Good | BS3: Good | BT3: Good | BU3: Good | BV3: Good | BW3: Good | BX3: Good | BY3: Good | BZ3: Good | CA3: Good | CB3: Good | CC3: Good | CD3: Good | CE3: Good | CF3: Good | CG3: Good | CH3: Good | CI3: Good | CJ3: Good | CK3: Good | CL3: Good | CM3: Good | CN3: Good | CO3: Good | CP3: Good | CQ3: Good | CR3: Good | CS3: Good | CT3: Good | CU3: Good | CV3: Good | CW3: Good | CX3: Good | CY3: Good | CZ3: Good | DA3: Good | DB3: Good | DC3: Good | DD3: Good | DE3: Good | DF3: Good | DG3: Good | DH3: Good | DI3: Good | DJ3: Good | DK3: Good | DL3: Good | DM3: Good | DN3: Maybe | DO3: Maybe | DP3: Maybe | DQ3: Good | DR3: Good | DS3: Maybe | DT3: Maybe | DU3: Good | DV3: Good | DW3: Good | DX3: Good | DY3: Good | DZ3: Good | EA3: Good | EB3: Good | EC3: Good | ED3: Good | EE3: Good | EF3: Good | EG3: Good | EH3: Good | EI3: Good | EJ3: Good | EK3: Good | EL3: Good | EM3: Good | EN3: Good | EO3: Good | EP3: Good | EQ3: Good | ER3: Good | ES3: Good | ET3: Good | EU3: Good | EV3: Good | EW3: Good | EX3: Good | EY3: Good | EZ3: Good | FA3: Good | FB3: Good | FC3: Good | FD3: Good | FE3: Good | FF3: Good | FG3: Good | FH3: Good | FI3: Good | FJ3: Good | FK3: Good | FL3: Good | FM3: Good | FN3: Good | FO3: Good | FP3: Good | FQ3: Good | FR3: Good | FS3: Good | FT3: Good | FU3: Good | FV3: Good | FW3: Good | FX3: Good | FY3: Good | FZ3: Good | GA3: Good | GB3: Good | GC3: Good | GD3: Good | GE3: Good | GF3: Good | GG3: Good | GH3: Good | GI3: Good | GJ3: Good
A4: MORPC_007 | AA4: Maybe | AB4: Good | AC4: Good | AD4: Good | AE4: Good | AF4: Good | AG4: Good | AH4: Good | AI4: Good | AJ4: Good | AK4: Good | AL4: Maybe | AM4: Good | AN4: Good | AO4: Good | AP4: Good | AQ4: Good | AR4: Good | AS4: Good | AT4: Maybe | AU4: Good | AV4: Good | AW4: Good | AX4: Good | AY4: Good | AZ4: Good | BA4: Good | BB4: Good | BC4: Good | BD4: Good | BE4: Good | BF4: Good | BG4: Good | BH4: Good | BI4: Bad | BJ4: Bad | BK4: Maybe | BL4: Good | BM4: Good | BN4: Good | BO4: Good | BP4: Good | BQ4: Good | BR4: Good | BS4: Good | BT4: Good | BU4: Good | BV4: Good | BW4: Good | BX4: Good | BY4: Good | BZ4: Good | CA4: Good | CB4: Good | CC4: Good | CD4: Good | CE4: Good | CF4: Good | CG4: Good | CH4: Good | CI4: Good | CJ4: Good | CK4: Good | CL4: Good | CM4: Good | CN4: Good | CO4: Good | CP4: Good | CQ4: Good | CR4: Good | CS4: Good | CT4: Good | CU4: Good | CV4: Good | CW4: Good | CX4: Good | CY4: Good | CZ4: Good | DA4: Good | DB4: Good | DC4: Good | DD4: Good | DE4: Good | DF4: Good | DG4: Good | DH4: Good | DI4: Good | DJ4: Good | DK4: Good | DL4: Maybe | DM4: Good | DN4: Good | DO4: Good | DP4: Good | DQ4: Good | DR4: Good | DS4: Good | DT4: Good | DU4: Good | DV4: Good | DW4: Good | DX4: Good | DY4: Good | DZ4: Good | EA4: Good | EB4: Good | EC4: Good | ED4: Good | EE4: Good | EF4: Good | EG4: Good | EH4: Good | EI4: Good | EJ4: Good | EK4: Good | EL4: Good | EM4: Good | EN4: Good | EO4: Good | EP4: Good | EQ4: Good | ER4: Good | ES4: Good | ET4: Good | EU4: Good | EV4: Good | EW4: Good | EX4: Maybe | EY4: Good | EZ4: Good | FA4: Good | FB4: Good | FC4: Good | FD4: Good | FE4: Good | FF4: Good | FG4: Good | FH4: Good | FI4: Good | FJ4: Good | FK4: Good | FL4: Good | FM4: Good | FN4: Good | FO4: Good | FP4: Good | FQ4: Good | FR4: Good | FS4: Good | FT4: Good | FU4: Good | FV4: Good | FW4: Good | FX4: Good | FY4: Good | FZ4: Good | GA4: Good | GB4: Good | GC4: Good | GD4: Bad | GE4: Bad | GF4: Bad | GG4: Bad | GH4: Bad | GI4: Bad | GJ4: Bad
A5: MORPC_012 | B5: Good | C5: Good | D5: Good | E5: Good | F5: Good | G5: Good | H5: Good | I5: Maybe | J5: Maybe | K5: Good | L5: Good | M5: Good | N5: Good | O5: Maybe | P5: Maybe | Q5: Maybe | R5: Good | S5: Maybe | T5: Good | U5: Good | V5: Good | W5: Good | X5: Good | Y5: Good | Z5: Good | AA5: Maybe | AB5: Good | AC5: Good | AD5: Good | AE5: Good | AF5: Maybe | AG5: Good | AH5: Good | AI5: Maybe | AJ5: Maybe | AK5: Maybe | AL5: Maybe | AM5: Good | AN5: Maybe | AO5: Maybe | AP5: Bad | AQ5: Bad | AR5: Bad | AS5: Bad | AT5: Bad | AU5: Bad | AV5: Good | AW5: Good | AX5: Good | AY5: Maybe | AZ5: Good | BA5: Good | BB5: Good | BC5: Good | BD5: Good | BE5: Good | BF5: Good | BG5: Maybe | BH5: Good | BI5: Good | BJ5: Bad | BK5: Bad | BL5: Bad | BM5: Bad | BN5: Bad | BO5: Bad | BP5: Bad | BQ5: Bad | BR5: Bad | BS5: Bad | BT5: Bad | BU5: Bad | BV5: Bad | BW5: Bad | BX5: Bad | BY5: Bad | BZ5: Bad | CA5: Bad | CB5: Bad | CC5: Bad | CD5: Bad | CE5: Bad | CF5: Bad | CG5: Bad | CH5: Bad | CI5: Bad | CJ5: Bad | CK5: Bad | CL5: Bad | CM5: Bad | CN5: Bad | CO5: Bad | CP5: Bad | CQ5: Bad | CR5: Bad | CS5: Bad | CT5: Bad | CU5: Bad | CV5: Bad | CW5: Bad | CX5: Bad | CY5: Bad | CZ5: Bad | DA5: Bad | DB5: Bad | DC5: Bad | DD5: Bad | DE5: Bad | DF5: Bad | DG5: Bad | DH5: Removed | DI5: Removed | DJ5: Removed | DK5: Removed | DL5: Removed | DM5: Removed | DN5: Removed | DO5: Removed | DP5: Removed | DQ5: Removed | DR5: Removed | DS5: Removed | DT5: Removed | DU5: Removed | DV5: Removed | DW5: Removed | DX5: Removed | DY5: Removed | DZ5: Removed | EA5: Removed | EB5: Removed | EC5: Removed | ED5: Removed | EE5: Removed | EF5: Removed | EG5: Removed | EH5: Removed | EI5: Removed | EJ5: Removed | EK5: Removed | EL5: Removed | EM5: Removed | EN5: Removed | EO5: Removed | EP5: Removed | EQ5: Removed | ER5: Removed | ES5: Removed | ET5: Removed | EU5: Removed | EV5: Removed | EW5: Removed | EX5: Removed | EY5: Removed | EZ5: Removed | FA5: Removed | FB5: Removed | FC5: Removed | FD5: Removed | FE5: Removed | FF5: Removed | FG5: Removed | FH5: Removed | FI5: Removed | FJ5: Removed | FK5: Removed | FL5: Removed | FM5: Removed | FN5: Removed | FO5: Removed | FP5: Removed | FQ5: Removed | FR5: Removed | FS5: Removed | FT5: Removed | FU5: Removed | FV5: Removed
A6: MORPC_014 | B6: Good | C6: Good | D6: Good | E6: Good | F6: Good | G6: Good | H6: Good | I6: Good | J6: Good | K6: Good | L6: Good | M6: Good | N6: Good | O6: Good | P6: Good | Q6: Good | R6: Good | S6: Good | T6: Good | U6: Good | V6: Good | W6: Good | X6: Bad | Y6: Good | Z6: Good | AA6: Good | AB6: Good | AC6: Good | AD6: Good | AE6: Bad | AF6: Good | AG6: Good | AH6: Good | AI6: Good | AJ6: Good | AK6: Good | AL6: Good | AM6: Good | AN6: Good | AO6: Good | AP6: Bad | AQ6: Good | AR6: Good | AS6: Good | AT6: Good | AU6: Good | AV6: Good | AW6: Good | AX6: Good | AY6: Maybe | AZ6: Good | BA6: Good | BB6: Good | BC6: Good | BD6: Good | BE6: Good | BF6: Good | BG6: Good | BH6: Good | BI6: Good | BJ6: Good | BK6: Good | BL6: Good | BM6: Good | BN6: Good | BO6: Good | BP6: Good | BQ6: Good | BR6: Good | BS6: Good | BT6: Good | BU6: Good | BV6: Good | BW6: Good | BX6: Good | BY6: Good | BZ6: Good | CA6: Good | CB6: Good | CC6: Good | CD6: Good | CE6: Good | CF6: Good | CG6: Good | CH6: Good | CI6: Good | CJ6: Good | CK6: Good | CL6: Good | CM6: Good | CN6: Good | CO6: Good | CP6: Good | CQ6: Good | CR6: Good | CS6: Good | CT6: Good | CU6: Good | CV6: Good | CW6: Good | CX6: Good | CY6: Good | CZ6: Good | DA6: Good | DB6: Good | DC6: Good | DD6: Good | DE6: Good | DF6: Good | DG6: Good | DH6: Good | DI6: Good | DJ6: Good | DK6: Good | DL6: Good | DM6: Good | DN6: Good | DO6: Good | DP6: Good | DQ6: Good | DR6: Good | DS6: Good | DT6: Good | DU6: Good | DV6: Good | DW6: Good | DX6: Good | DY6: Good | DZ6: Good | EA6: Good | EB6: Good | EC6: Good | ED6: Bad | EE6: Good | EF6: Good | EG6: Good | EH6: Good | EI6: Good | EJ6: Good | EK6: Good | EL6: Good | EM6: Good | EN6: Good | EO6: Good | EP6: Good | EQ6: Good | ER6: Good | ES6: Good | ET6: Good | EU6: Good | EV6: Good | EW6: Good | EX6: Good | EY6: Good | EZ6: Good | FA6: Good | FB6: Good | FC6: Good | FD6: Good | FE6: Good | FF6: Good | FG6: Good | FH6: Good | FI6: Good | FJ6: Good | FK6: Good | FL6: Good | FM6: Good | FN6: Good | FO6: Good | FP6: Good | FQ6: Good | FR6: Good | FS6: Good | FT6: Good | FU6: Good | FV6: Good | FW6: Good | FX6: Good | FY6: Good | FZ6: Good | GA6: Good | GB6: Good | GC6: Good | GD6: Good | GE6: Good | GF6: Good | GG6: Good | GH6: Good | GI6: Good | GJ6: Good
A7: MORPC_017 | X7: Good | Y7: Good | Z7: Good | AA7: Good | AB7: Good | AC7: Good | AD7: Good | AE7: Maybe | AF7: Good | AG7: Maybe | AH7: Maybe | AI7: Maybe | AJ7: Maybe | AK7: Maybe | AL7: Maybe | AM7: Maybe | AN7: Maybe | AO7: Maybe | AP7: Maybe | AQ7: Good | AR7: Maybe | AS7: Good | AT7: Good | AU7: Good | AV7: Good | AW7: Good | AX7: Good | AY7: Good | AZ7: Good | BA7: Good | BB7: Good | BC7: Good | BD7: Good | BE7: Good | BF7: Good | BG7: Good | BH7: Good | BI7: Good | BJ7: Good | BK7: Good | BL7: Good | BM7: Good | BN7: Good | BO7: Good | BP7: Good | BQ7: Good | BR7: Good | BS7: Good | BT7: Good | BU7: Good | BV7: Good | BW7: Good | BX7: Good | BY7: Good | BZ7: Good | CA7: Good | CB7: Good | CC7: Good | CD7: Good | CE7: Good | CF7: Good | CG7: Good | CH7: Good | CI7: Good | CJ7: Good | CK7: Good | CL7: Good | CM7: Good | CN7: Good | CO7: Bad | CP7: Bad | CQ7: Bad | CR7: Bad | CS7: Bad | CT7: Bad | CU7: Bad | CV7: Bad | CW7: Bad | CX7: Bad | CY7: Bad | CZ7: Maybe | DA7: Bad | DB7: Bad | DC7: Bad | DD7: Bad | DE7: Bad | DF7: Removed | DG7: Removed | DH7: Removed | DI7: Removed | DJ7: Removed | DK7: Removed | DL7: Removed | DM7: Removed | DN7: Removed | DO7: Removed | DP7: Removed | DQ7: Removed | DR7: Removed | DS7: Removed | DT7: Removed | DU7: Removed | DV7: Removed | DW7: Removed | DX7: Removed | DY7: Removed | DZ7: Removed | EA7: Removed | EB7: Removed | EC7: Removed | ED7: Removed | EE7: Removed | EF7: Removed | EG7: Removed | EH7: Removed | EI7: Removed | EJ7: Removed | EK7: Removed | EL7: Removed | EM7: Removed | EN7: Removed | EO7: Removed | EP7: Removed | EQ7: Removed | ER7: Removed | ES7: Removed | ET7: Removed | EU7: Removed | EV7: Removed | EW7: Removed | EX7: Removed | EY7: Removed | EZ7: Removed | FA7: Removed | FB7: Removed | FC7: Removed | FD7: Removed | FE7: Removed | FF7: Removed | FG7: Removed | FH7: Removed | FI7: Removed | FJ7: Removed | FK7: Removed | FL7: Removed | FM7: Removed | FN7: Removed | FO7: Removed | FP7: Removed | FQ7: Removed | FR7: Removed | FS7: Removed | FT7: Removed | FU7: Removed | FV7: Removed
A8: MORPC_022 | AH8: Good | AI8: Good | AJ8: Good | AK8: Good | AL8: Good | AM8: Good | AN8: Good | AO8: Good | AP8: Good | AQ8: Good | AR8: Good | AS8: Good | AT8: Maybe | AU8: Good | AV8: Good | AW8: Bad | AX8: Bad | AY8: Bad | AZ8: Bad | BA8: Bad | BB8: Bad | BC8: Bad | BD8: Bad | BE8: Bad | BF8: Bad | BG8: Bad | BH8: Bad | BI8: Bad | BJ8: Bad | BK8: Bad | BL8: Bad | BM8: Bad | BN8: Bad | BO8: Bad | BP8: Bad | BQ8: Bad | BR8: Bad | BS8: Bad | BT8: Bad | BU8: Bad | BV8: Bad | BW8: Bad | BX8: Bad | BY8: Bad | BZ8: Bad | CA8: Bad | CB8: Bad | CC8: Bad | CD8: Bad | CE8: Bad | CF8: Bad | CG8: Bad | CH8: Bad | CI8: Bad | CJ8: Bad | CK8: Bad | CL8: Bad | CM8: Bad | CN8: Bad | CO8: Bad | CP8: Bad
A9: MORPC_022 | B9: Good | C9: Good | D9: Good | E9: Good | F9: Good | G9: Good | H9: Good | I9: Good | J9: Good | K9: Good | L9: Good | M9: Good | N9: Good | O9: Good | P9: Good | Q9: Maybe | R9: Maybe | S9: Maybe | T9: Maybe | U9: Bad | V9: Bad | W9: Bad
A10: MORPC_023 | B10: Good | C10: Good | D10: Good | E10: Bad | F10: Good | G10: Good | H10: Good | I10: Good | J10: Good | K10: Good | L10: Good | M10: Good | N10: Good | O10: Good | P10: Good | Q10: Good | R10: Good | S10: Good | T10: Good | U10: Good | V10: Good | W10: Good | X10: Good | Y10: Good | Z10: Good | AA10: Good | AB10: Good | AC10: Good | AD10: Good | AE10: Good | AF10: Good | AG10: Good | AH10: Bad | AI10: Good | AJ10: Good | AK10: Good | AL10: Maybe | AM10: Good | AN10: Good | AO10: Good | AP10: Good | AQ10: Good | AR10: Good | AS10: Bad | AT10: Bad | AU10: Bad | AV10: Bad | AW10: Bad | AX10: Bad | AY10: Bad | AZ10: Bad | BA10: Bad | BB10: Bad | BC10: Bad | BD10: Bad | BE10: Bad | BF10: Bad | BG10: Bad | BH10: Bad | BI10: Bad | BJ10: Bad | BK10: Bad | BL10: Bad | BM10: Bad | BN10: Bad | BO10: Bad | BP10: Bad | BQ10: Bad | BR10: Bad | BS10: Bad | BT10: Bad | BU10: Bad | BV10: Bad | BW10: Bad | BX10: Bad | BY10: Bad | BZ10: Bad | CA10: Bad | CB10: Bad | CC10: Bad | CD10: Bad | CE10: Bad | CF10: Bad | CG10: Bad | CH10: Bad | CI10: Bad | CJ10: Bad | CK10: Bad | CL10: Bad | CM10: Bad | CN10: Bad | CO10: Bad | CP10: Bad | CQ10: Maybe | CR10: Maybe | CS10: Maybe | CT10: Bad | CU10: Bad | CV10: Bad | CW10: Bad | CX10: Bad | CY10: Bad | CZ10: Bad | DA10: Bad | DB10: Bad | DC10: Bad | DD10: Bad | DE10: Bad | DF10: Bad | DG10: Bad | DH10: Bad | DI10: Bad | DJ10: Bad | DK10: Bad | DL10: Bad | DM10: Removed | DN10: Removed | DO10: Removed | DP10: Removed | DQ10: Removed | DR10: Removed | DS10: Removed | DT10: Removed | DU10: Removed | DV10: Removed | DW10: Removed | DX10: Removed | DY10: Removed | DZ10: Removed | EA10: Removed | EB10: Removed | EC10: Removed | ED10: Removed | EE10: Removed | EF10: Removed | EG10: Removed | EH10: Removed | EI10: Removed | EJ10: Removed | EK10: Removed | EL10: Removed | EM10: Removed | EN10: Removed | EO10: Removed | EP10: Removed | EQ10: Removed | ER10: Removed | ES10: Removed | ET10: Removed | EU10: Removed | EV10: Removed | EW10: Removed | EX10: Removed | EY10: Removed | EZ10: Removed | FA10: Removed | FB10: Removed | FC10: Removed | FD10: Removed | FE10: Removed | FF10: Removed | FG10: Removed | FH10: Removed | FI10: Removed | FJ10: Removed | FK10: Removed | FL10: Removed | FM10: Removed | FN10: Removed | FO10: Removed | FP10: Removed | FQ10: Removed | FR10: Removed | FS10: Removed | FT10: Removed | FU10: Removed | FV10: Removed
A11: MORPC_024 | G11: Good | H11: Good | I11: Good | J11: Good | K11: Good | L11: Good | M11: Good | N11: Bad | O11: Bad | P11: Bad | Q11: Bad | R11: Bad | S11: Bad | T11: Bad | U11: Good | V11: Good | W11: Good | X11: Good | Y11: Good | Z11: Good | AA11: Good | AB11: Good | AC11: Good | AD11: Good | AE11: Good | AF11: Good | AG11: Bad | AH11: Good | AI11: Good | AJ11: Good | AK11: Good | AL11: Good | AM11: Good | AN11: Bad | AO11: Good | AP11: Good | AQ11: Good | AR11: Good | AS11: Good | AT11: Good | AU11: Good | AV11: Good | AW11: Good | AX11: Good | AY11: Good | AZ11: Good | BA11: Good | BB11: Good | BC11: Good | BD11: Good | BE11: Good | BF11: Good | BG11: Bad | BH11: Bad | BI11: Bad | BJ11: Bad | BK11: Bad | BL11: Bad | BM11: Bad | BN11: Bad | BO11: Bad | BP11: Bad | BQ11: Bad | BR11: Bad | BS11: Bad | BT11: Bad | BU11: Bad | BV11: Bad | BW11: Bad | BX11: Bad | BY11: Bad | BZ11: Bad | CA11: Bad | CB11: Bad | CC11: Bad | CD11: Bad | CE11: Bad | CF11: Bad | CG11: Bad | CH11: Bad | CI11: Bad | CJ11: Bad | CK11: Bad | CL11: Bad | CM11: Bad | CN11: Bad | CO11: Bad | CP11: Bad | CQ11: Bad | CR11: Bad | CS11: Bad | CT11: Bad | CU11: Bad | CV11: Bad | CW11: Bad | CX11: Bad | CY11: Bad | CZ11: Bad | DA11: Bad | DB11: Bad | DC11: Bad | DD11: Bad | DE11: Bad | DF11: Removed | DG11: Removed | DH11: Removed | DI11: Removed | DJ11: Removed | DK11: Removed | DL11: Removed | DM11: Removed | DN11: Removed | DO11: Removed | DP11: Removed | DQ11: Removed | DR11: Removed | DS11: Removed | DT11: Removed | DU11: Removed | DV11: Removed | DW11: Removed | DX11: Removed | DY11: Removed | DZ11: Removed | EA11: Removed | EB11: Removed | EC11: Removed | ED11: Removed | EE11: Removed | EF11: Removed | EG11: Removed | EH11: Removed | EI11: Removed | EJ11: Removed | EK11: Removed | EL11: Removed | EM11: Removed | EN11: Removed | EO11: Removed | EP11: Removed | EQ11: Removed | ER11: Removed | ES11: Removed | ET11: Removed | EU11: Removed | EV11: Removed | EW11: Removed | EX11: Removed | EY11: Removed | EZ11: Removed | FA11: Removed | FB11: Removed | FC11: Removed | FD11: Removed | FE11: Removed | FF11: Removed | FG11: Removed | FH11: Removed | FI11: Removed | FJ11: Removed | FK11: Removed | FL11: Removed | FM11: Removed | FN11: Removed | FO11: Removed | FP11: Removed | FQ11: Removed | FR11: Removed | FS11: Removed | FT11: Removed | FU11: Removed | FV11: Removed
A12: MORPC_025 | B12: Good | C12: Bad | D12: Bad | E12: Bad | F12: Good | G12: Good | H12: Good | I12: Good | J12: Good | K12: Good | L12: Good | M12: Good | N12: Good | O12: Good | P12: Good | Q12: Good | R12: Good | S12: Good | T12: Good | U12: Good | V12: Good | W12: Good | X12: Bad | Y12: Good | Z12: Good | AA12: Good | AB12: Good | AC12: Maybe | AD12: Good | AE12: Good | AF12: Good | AG12: Good | AH12: Good | AI12: Good | AJ12: Good | AK12: Good | AL12: Good | AM12: Good | AN12: Good | AO12: Good | AP12: Good | AQ12: Good | AR12: Good | AS12: Good | AT12: Good | AU12: Good | AV12: Good | AW12: Good | AX12: Good | AY12: Good | AZ12: Good | BA12: Good | BB12: Good | BC12: Good | BD12: Good | BE12: Good | BF12: Good | BG12: Good | BH12: Good | BI12: Good | BJ12: Good | BK12: Good | BL12: Good | BM12: Good | BN12: Good | BO12: Good | BP12: Good | BQ12: Good | BR12: Good | BS12: Good | BT12: Good | BU12: Good | BV12: Good | BW12: Good | BX12: Good | BY12: Good | BZ12: Good | CA12: Good | CB12: Good | CC12: Good | CD12: Good | CE12: Good | CF12: Good | CG12: Good | CH12: Good | CI12: Good | CJ12: Good | CK12: Good | CL12: Good | CM12: Good | CN12: Good | CO12: Good | CP12: Good | CQ12: Good | CR12: Good | CS12: Good | CT12: Good | CU12: Good | CV12: Good | CW12: Good | CX12: Good | CY12: Good | CZ12: Good | DA12: Good | DB12: Good | DC12: Good | DD12: Good | DE12: Good | DF12: Good | DG12: Good | DH12: Good | DI12: Good | DJ12: Good | DK12: Good | DL12: Good | DM12: Good | DN12: Good | DO12: Good | DP12: Good | DQ12: Good | DR12: Good | DS12: Good | DT12: Good | DU12: Good | DV12: Good | DW12: Good | DX12: Good | DY12: Good | DZ12: Good | EA12: Good | EB12: Good | EC12: Good | ED12: Good | EE12: Good | EF12: Good | EG12: Good | EH12: Good | EI12: Good | EJ12: Good | EK12: Good | EL12: Good | EM12: Good | EN12: Good | EO12: Good | EP12: Good | EQ12: Good | ER12: Good | ES12: Good | ET12: Good | EU12: Good | EV12: Good | EW12: Good | EX12: Good | EY12: Good | EZ12: Good | FA12: Good | FB12: Good | FC12: Good | FD12: Good | FE12: Good | FF12: Good | FG12: Good | FH12: Good | FI12: Good | FJ12: Good | FK12: Good | FL12: Good | FM12: Bad | FN12: Bad | FO12: Bad | FP12: Bad | FQ12: Bad | FR12: Bad | FS12: Bad | FT12: Bad | FU12: Bad | FV12: Bad | FW12: Bad | FX12: Bad | FY12: Bad | FZ12: Bad | GA12: Bad | GB12: Bad | GC12: Bad | GD12: Bad | GE12: Bad | GF12: Bad | GG12: Bad | GH12: Bad | GI12: Bad | GJ12: Bad
A13: MORPC_026 | B13: Good | C13: Good | D13: Good | E13: Good | F13: Good | G13: Good | H13: Good | I13: Good | J13: Good | K13: Good | L13: Good | M13: Good | N13: Good | O13: Good | P13: Good | Q13: Good | R13: Good | S13: Good | T13: Good | U13: Good | V13: Good | W13: Good | X13: Good | Y13: Good | Z13: Good | AA13: Good | AB13: Good | AC13: Bad | AD13: Maybe | AE13: Good | AF13: Good | AG13: Good | AH13: Good | AI13: Bad | AJ13: Good | AK13: Good | AL13: Good | AM13: Good | AN13: Good | AO13: Good | AP13: Good | AQ13: Good | AR13: Good | AS13: Bad | AT13: Bad | AU13: Bad | AV13: Bad | AW13: Bad | AX13: Bad | AY13: Bad | AZ13: Bad | BA13: Bad | BB13: Bad | BC13: Bad | BD13: Bad | BE13: Bad | BF13: Bad | BG13: Bad | BH13: Bad | BI13: Bad | BJ13: Bad | BK13: Bad | BL13: Bad | BM13: Bad | BN13: Bad | BO13: Bad | BP13: Bad | BQ13: Bad | BR13: Bad | BS13: Bad | BT13: Bad | BU13: Bad | BV13: Bad | BW13: Bad | BX13: Bad | BY13: Bad | BZ13: Bad | CA13: Bad | CB13: Bad | CC13: Bad | CD13: Bad | CE13: Bad | CF13: Bad | CG13: Bad | CH13: Bad | CI13: Bad | CJ13: Bad | CK13: Bad | CL13: Bad | CM13: Maybe | CN13: Maybe | CO13: Maybe | CP13: Maybe | CQ13: Maybe | CR13: Maybe | CS13: Maybe | CT13: Maybe | CU13: Maybe | CV13: Maybe | CW13: Maybe | CX13: Maybe | CY13: Maybe | CZ13: Maybe | DA13: Maybe | DB13: Maybe | DC13: Maybe | DD13: Maybe | DE13: Bad | DF13: Good | DG13: Good | DH13: Good | DI13: Good | DJ13: Good | DK13: Good | DL13: Removed | DM13: Removed | DN13: Removed | DO13: Removed | DP13: Removed | DQ13: Removed | DR13: Removed | DS13: Removed | DT13: Removed | DU13: Removed | DV13: Removed | DW13: Removed | DX13: Removed | DY13: Removed | DZ13: Removed | EA13: Removed | EB13: Removed | EC13: Removed | ED13: Removed | EE13: Removed | EF13: Removed | EG13: Removed | EH13: Removed | EI13: Removed | EJ13: Removed | EK13: Removed | EL13: Removed | EM13: Removed | EN13: Removed | EO13: Removed | EP13: Removed | EQ13: Removed | ER13: Removed | ES13: Removed | ET13: Removed | EU13: Removed | EV13: Removed | EW13: Removed | EX13: Removed | EY13: Removed | EZ13: Removed | FA13: Removed | FB13: Removed | FC13: Removed | FD13: Removed | FE13: Removed | FF13: Removed | FG13: Removed | FH13: Removed | FI13: Removed | FJ13: Removed | FK13: Removed | FL13: Removed | FM13: Removed | FN13: Removed | FO13: Removed | FP13: Removed | FQ13: Removed | FR13: Removed | FS13: Removed | FT13: Removed | FU13: Removed | FV13: Removed
A14: MORPC_027 | Q14: Maybe | R14: Maybe | S14: Good | T14: Good | U14: Good | V14: Good | W14: Good | X14: Good | Y14: Good | Z14: Good | AA14: Good | AB14: Good | AC14: Good | AD14: Good | AE14: Good | AF14: Good | AG14: Good | AH14: Good | AI14: Good | AJ14: Good | AK14: Good | AL14: Good | AM14: Good | AN14: Good | AO14: Good | AP14: Good | AQ14: Good | AR14: Good | AS14: Good | AT14: Maybe | AU14: Good | AV14: Good | AW14: Good | AX14: Good | AY14: Good | AZ14: Good | BA14: Good | BB14: Good | BC14: Good | BD14: Good | BE14: Good | BF14: Good | BG14: Good | BH14: Good | BI14: Good | BJ14: Good | BK14: Good | BL14: Good | BM14: Good | BN14: Good | BO14: Good | BP14: Good | BQ14: Good | BR14: Good | BS14: Good | BT14: Good | BU14: Good | BV14: Good | BW14: Good | BX14: Good | BY14: Good | BZ14: Good | CA14: Good | CB14: Good | CC14: Good | CD14: Good | CE14: Good | CF14: Good | CG14: Good | CH14: Good | CI14: Good | CJ14: Good | CK14: Good | CL14: Good | CM14: Good | CN14: Good | CO14: Good | CP14: Good | CQ14: Good | CR14: Good | CS14: Good | CT14: Good | CU14: Good | CV14: Good | CW14: Good | CX14: Good | CY14: Good | CZ14: Good | DA14: Good | DB14: Good | DC14: Good | DD14: Good | DE14: Good | DF14: Good | DG14: Good | DH14: Good | DI14: Good | DJ14: Good | DK14: Good | DL14: Good | DM14: Good | DN14: Good | DO14: Good | DP14: Good | DQ14: Good | DR14: Good | DS14: Good | DT14: Good | DU14: Good | DV14: Good | DW14: Good | DX14: Good | DY14: Good | DZ14: Good | EA14: Good | EB14: Good | EC14: Good | ED14: Good | EE14: Bad | EF14: Good | EG14: Good | EH14: Good | EI14: Good | EJ14: Good | EK14: Good | EL14: Good | EM14: Good | EN14: Good | EO14: Bad | EP14: Bad | EQ14: Good | ER14: Good | ES14: Good | ET14: Good | EU14: Good | EV14: Good | EW14: Good | EX14: Bad | EY14: Bad | EZ14: Bad | FA14: Bad | FB14: Bad | FC14: Bad | FD14: Bad | FE14: Bad | FF14: Bad | FG14: Good | FH14: Good | FI14: Bad | FJ14: Bad | FK14: Bad | FL14: Bad | FM14: Good | FN14: Good | FO14: Good | FP14: Good | FQ14: Good | FR14: Good | FS14: Good | FT14: Good | FU14: Good | FV14: Good | FW14: Good | FX14: Good | FY14: Good | FZ14: Good | GA14: Good | GB14: Good | GC14: Good | GD14: Good | GE14: Good | GF14: Good | GG14: Good | GH14: Good | GI14: Good | GJ14: Good
